ERROR 2023-09-07 22:16:49,900 Internal Server Error: /accounts/signup/ C:\Users\Admin\PycharmProjects\news\env\lib\site-packages\django\utils\log.py (<class 'smtplib.SMTPAuthenticationError'>, SMTPAuthenticationError(535, b'5.7.8 Error: authentication failed: Invalid user or password! 1694146609-jGRJ0L6sJmI0'), <traceback object at 0x000001CA44377A88>)
Traceback (most recent call last):
  File "C:\Users\Admin\PycharmProjects\news\env\lib\site-packages\django\core\handlers\exception.py", line 47, in inner
    response = get_response(request)
  File "C:\Users\Admin\PycharmProjects\news\env\lib\site-packages\django\core\handlers\base.py", line 181, in _get_response
    response = wrapped_callback(request, *callback_args, **callback_kwargs)
  File "C:\Users\Admin\PycharmProjects\news\env\lib\site-packages\django\views\generic\base.py", line 70, in view
    return self.dispatch(request, *args, **kwargs)
  File "C:\Users\Admin\PycharmProjects\news\env\lib\site-packages\django\utils\decorators.py", line 43, in _wrapper
    return bound_method(*args, **kwargs)
  File "C:\Users\Admin\PycharmProjects\news\env\lib\site-packages\allauth\decorators.py", line 20, in wrap
    resp = function(request, *args, **kwargs)
  File "C:\Users\Admin\PycharmProjects\news\env\lib\site-packages\django\utils\decorators.py", line 43, in _wrapper
    return bound_method(*args, **kwargs)
  File "C:\Users\Admin\PycharmProjects\news\env\lib\site-packages\django\views\decorators\debug.py", line 89, in sensitive_post_parameters_wrapper
    return view(request, *args, **kwargs)
  File "C:\Users\Admin\PycharmProjects\news\env\lib\site-packages\allauth\account\views.py", line 234, in dispatch
    return super(SignupView, self).dispatch(request, *args, **kwargs)
  File "C:\Users\Admin\PycharmProjects\news\env\lib\site-packages\allauth\account\views.py", line 78, in dispatch
    request, *args, **kwargs
  File "C:\Users\Admin\PycharmProjects\news\env\lib\site-packages\allauth\account\views.py", line 207, in dispatch
    return super(CloseableSignupMixin, self).dispatch(request, *args, **kwargs)
  File "C:\Users\Admin\PycharmProjects\news\env\lib\site-packages\django\views\generic\base.py", line 98, in dispatch
    return handler(request, *args, **kwargs)
  File "C:\Users\Admin\PycharmProjects\news\env\lib\site-packages\allauth\account\views.py", line 105, in post
    response = self.form_valid(form)
  File "C:\Users\Admin\PycharmProjects\news\env\lib\site-packages\allauth\account\views.py", line 256, in form_valid
    self.get_success_url(),
  File "C:\Users\Admin\PycharmProjects\news\env\lib\site-packages\allauth\account\utils.py", line 192, in complete_signup
    signal_kwargs=signal_kwargs,
  File "C:\Users\Admin\PycharmProjects\news\env\lib\site-packages\allauth\account\utils.py", line 168, in perform_login
    response = adapter.pre_login(request, user, **hook_kwargs)
  File "C:\Users\Admin\PycharmProjects\news\env\lib\site-packages\allauth\account\adapter.py", line 412, in pre_login
    send_email_confirmation(request, user, signup=signup, email=email)
  File "C:\Users\Admin\PycharmProjects\news\env\lib\site-packages\allauth\account\utils.py", line 319, in send_email_confirmation
    email_address.send_confirmation(request, signup=signup)
  File "C:\Users\Admin\PycharmProjects\news\env\lib\site-packages\allauth\account\models.py", line 59, in send_confirmation
    confirmation.send(request, signup=signup)
  File "C:\Users\Admin\PycharmProjects\news\env\lib\site-packages\allauth\account\models.py", line 166, in send
    get_adapter(request).send_confirmation_mail(request, self, signup)
  File "C:\Users\Admin\PycharmProjects\news\env\lib\site-packages\allauth\account\adapter.py", line 549, in send_confirmation_mail
    self.send_mail(email_template, emailconfirmation.email_address.email, ctx)
  File "C:\Users\Admin\PycharmProjects\news\env\lib\site-packages\allauth\account\adapter.py", line 140, in send_mail
    msg.send()
  File "C:\Users\Admin\PycharmProjects\news\env\lib\site-packages\django\core\mail\message.py", line 284, in send
    return self.get_connection(fail_silently).send_messages([self])
  File "C:\Users\Admin\PycharmProjects\news\env\lib\site-packages\django\core\mail\backends\smtp.py", line 102, in send_messages
    new_conn_created = self.open()
  File "C:\Users\Admin\PycharmProjects\news\env\lib\site-packages\django\core\mail\backends\smtp.py", line 69, in open
    self.connection.login(self.username, self.password)
  File "C:\Users\Admin\AppData\Local\Programs\Python\Python37\lib\smtplib.py", line 730, in login
    raise last_exception
  File "C:\Users\Admin\AppData\Local\Programs\Python\Python37\lib\smtplib.py", line 721, in login
    initial_response_ok=initial_response_ok)
  File "C:\Users\Admin\AppData\Local\Programs\Python\Python37\lib\smtplib.py", line 642, in auth
    raise SMTPAuthenticationError(code, resp)
smtplib.SMTPAuthenticationError: (535, b'5.7.8 Error: authentication failed: Invalid user or password! 1694146609-jGRJ0L6sJmI0')
